Workbook

Sheet INICIO
B2: 💰 SIMULADOR DE INVERSIONES COLOMBIA
B3: Herramienta interactiva de comparación de instrumentos financieros
B4: Proyecto Matemática Fundamental • Universidad Compensar • Equipo C • Marzo 2026
B7: 📖 ¿CÓMO USAR ESTA APLICACIÓN?
B8: 1️⃣ Ingresa tu capital, años e inflación en la hoja SIMULADOR | C8: Las celdas editables están en azul sobre fondo amarillo
B9: 2️⃣ Compara 5 opciones de inversión automáticamente | C9: Cuenta Ahorro, CDT 90d, CDT 360d, FPV Conservador y Moderado
B10: 3️⃣ Define tu meta de ahorro en la hoja MI META | C10: Calcula cuánto tiempo necesitas para alcanzar cualquier monto
B11: 4️⃣ Consulta tasas reales en TASAS EN VIVO | C11: ="Datos de la Superintendencia Financiera de Colombia ("&CHOOSE(VALUE(MID(_DATOS_API!D3,6,2)),"enero","febrero","marzo","abril","mayo","junio","julio","agosto","septiembre","octubre","noviembre","diciembre")&" "&LEFT(_DATOS_API!D3,4)&")" -> Datos de la Superintendencia Financiera de Colombia (marzo 2026)
B13: 🗂️ NAVEGACIÓN
B14: 📊 SIMULADOR | C14: Compara 5 alternativas de inversión con interés compuesto. Ingresa tu capital y ve resultados al instante.
B15: 🎯 MI META | C15: ¿Cuánto tiempo necesitas para alcanzar tu meta de ahorro? Usa logaritmos para calcular el tiempo exacto.
B16: 🌐 TASAS EN VIVO | C16: ="Tasas CDT reales de bancos colombianos."&CHAR(10)&"Datos de la Superintendencia Financiera ("&CHOOSE(VALUE(MID(_DATOS_API!D3,6,2)),"enero","febrero","marzo","abril","mayo","junio","julio","agosto","septiembre","octubre","noviembre","diciembre")&" "&LEFT(_DATOS_API!D3,4)&")." -> Tasas CDT reales de bancos colombianos. Datos de la Superintendencia Financiera (marzo 2026).
B18: 🧮 CONCEPTOS MATEMÁTICOS APLICADOS
B19: CONJUNTOS NUMÉRICOS | C19: ℕ (periodos), ℤ (diferencias), ℚ (tasas = fracciones), ℝ\ℚ (número e ≈ 2.718), ℝ (todos los valores financieros)
B20: POLINOMIOS ARITMÉTICOS | C20: Jerarquía de operaciones: paréntesis → potencias → multiplicación → suma. Aplicado en cada fórmula del simulador.
B21: PROPORCIONALIDAD Y PORCENTAJES | C21: Tasas de interés (%), inflación (%), retención en la fuente (4%). Regla de tres para convertir tasas entre periodicidades.
B22: EXPRESIONES ALGEBRAICAS | C22: VF = VP × (1 + i)^t — Función exponencial de interés compuesto. Ecuaciones para despejar variables.
B23: LOGARITMOS | C23: t = ln(VF/VP) / ln(1+i) — Despeje del tiempo usando logaritmo natural. Aplicado en MI META y punto de equilibrio.
B24: FUNCIONES Y VARIABILIDAD | C24: Cada alternativa define f(t) = VP·(1+i)^t. Comparar funciones = analizar crecimiento y tomar decisiones financieras.
B26: 📐 FÓRMULAS CLAVE
B27: Tasa Efectiva Anual (TEA) | C27: TEA = (1 + i_nom / n)^n − 1
B28: Valor Futuro (interés compuesto) | C28: VF = VP × (1 + TEA)^t
B29: Valor Futuro Real | C29: VF_real = VF_neto / (1 + π)^t
B30: Tiempo para meta (logaritmos) | C30: t = ln(VF_meta / VP) / ln(1 + TEA)
B31: Tiempo para duplicar | C31: t = ln(2) / ln(1 + TEA)
B32: Regla del 72 (aproximación) | C32: t ≈ 72 / (tasa × 100)
B34: 📌 Fuentes: Superintendencia Financiera de Colombia (datos.gov.co) | Banco de la República | DANE (IPC dic 2025: 5.1%)
B35: Proyecto Matemática Fundamental — Universidad Compensar — Marzo 2026

Sheet SIMULADOR
A1: 💰 SIMULADOR DE INVERSIONES COLOMBIA
A2: Compara opciones y encuentra la mejor inversión para ti
A3: 📝 TUS DATOS
A4: ¿Cuánto dinero quieres invertir? | B4: 10000000 | C4: 💡 Escribe el monto en pesos colombianos
A5: ¿Por cuántos años? | B5: 5 | C5: 💡 Mínimo 1 año, máximo 30 años
A6: Inflación anual estimada | B6: 0.051 | C6: 💡 IPC Colombia dic 2025: 5.1% (DANE)
A7: Retención en la fuente | B7: 0.04 | C7: 💡 4% sobre ganancias (fijado por ley)
A9: 📊 COMPARACIÓN DE INVERSIONES
B11: 🏦 Cuenta Ahorro | C11: 📄 CDT 90 días | D11: 📄 CDT 360 días | E11: 📈 FPV Conservador | F11: 📈 FPV Moderado
A12: Tasa de interés anual | B12: ='TASAS EN VIVO'!C6 -> 0.11 | C12: ='TASAS EN VIVO'!C7 -> 0.1135 | D12: ='TASAS EN VIVO'!C8 -> 0.1392 | E12: ='TASAS EN VIVO'!C9 -> 0.0726 | F12: ='TASAS EN VIVO'!C10 -> 0.1042
A13: Frecuencia de ganancia | B13: Mensual (12/año) | C13: Trimestral (4/año) | D13: Anual (1/año) | E13: Anual (1/año) | F13: Anual (1/año)
B14: 12 | C14: 4 | D14: 1 | E14: 1 | F14: 1
B15: =(1+B12/B14)^B14-1 -> 0.11571884 | C15: =(1+C12/C14)^C14-1 -> 0.11842288 | D15: =(1+D12/D14)^D14-1 -> 0.1392 | E15: =(1+E12/E14)^E14-1 -> 0.0726 | F15: =(1+F12/F14)^F14-1 -> 0.1042
A17: 💵 ¿Cuánto tendrás al final? | B17: =$B$4*(1+B15)^$B$5 -> 17289157 | C17: =$B$4*(1+C15)^$B$5 -> 17499684 | D17: =$B$4*(1+D15)^$B$5 -> 19186682 | E17: =$B$4*(1+E15)^$B$5 -> 14196751 | F17: =$B$4*(1+F15)^$B$5 -> 16414918
A18: 💰 Ganancia bruta total | B18: =B17-$B$4 -> 7289157.3 | C18: =C17-$B$4 -> 7499684 | D18: =D17-$B$4 -> 9186682.2 | E18: =E17-$B$4 -> 4196750.9 | F18: =F17-$B$4 -> 6414917.9
A19: 📋 Impuestos descontados | B19: =B18*$B$7 -> 291566.29 | C19: =C18*$B$7 -> 299987.36 | D19: =D18*$B$7 -> 367467.29 | E19: =E18*$B$7 -> 167870.04 | F19: =F18*$B$7 -> 256596.71
A20: 💵 Recibes después de impuestos | B20: =B17-B19 -> 16997591 | C20: =C17-C19 -> 17199697 | D20: =D17-D19 -> 18819215 | E20: =E17-E19 -> 14028881 | F20: =F17-F19 -> 16158321
A21: 💵 Valor real (descontando inflación) | B21: =B20/(1+$B$6)^$B$5 -> 13254819 | C21: =C20/(1+$B$6)^$B$5 -> 13412422 | D21: =D20/(1+$B$6)^$B$5 -> 14675332 | E21: =E20/(1+$B$6)^$B$5 -> 10939802 | F21: =F20/(1+$B$6)^$B$5 -> 12600351
A22: 📊 Ganancia real neta | B22: =B21-$B$4 -> 3254818.8 | C22: =C21-$B$4 -> 3412421.9 | D22: =D21-$B$4 -> 4675331.5 | E22: =E21-$B$4 -> 939801.65 | F22: =F21-$B$4 -> 2600351.4
A23: 📈 Rendimiento real (%) | B23: =B22/$B$4 -> 0.32548188 | C23: =C22/$B$4 -> 0.34124219 | D23: =D22/$B$4 -> 0.46753315 | E23: =E22/$B$4 -> 0.093980165 | F23: =F22/$B$4 -> 0.26003514
A24: 🏆 Ranking | B24: =RANK(B22,$B$22:$F$22)&"°" -> 3° | C24: =RANK(C22,$B$22:$F$22)&"°" -> 2° | D24: =RANK(D22,$B$22:$F$22)&"°" -> 1° | E24: =RANK(E22,$B$22:$F$22)&"°" -> 5° | F24: =RANK(F22,$B$22:$F$22)&"°" -> 4°
A26: 🏆 NUESTRA RECOMENDACIÓN
A28: 🥇 Tu mejor opción es: | B28: =IF(MAX(B22:F22)=B22,B11,IF(MAX(B22:F22)=C22,C11,IF(MAX(B22:F22)=D22,D11,IF(MAX(B22:F22)=E22,E11,F11)))) -> 📄 CDT 360 días
A29: 🏦 Total que recibirás: | B29: =MAX(B20:F20) -> 18819215 | C29: (después de impuestos)
A30: 💰 Ganancia real: | B30: =MAX(B22:F22) -> 4675331.5 | C30: (descontando inflación e impuestos)
A31: 📈 Rendimiento real: | B31: =MAX(B23:F23) -> 0.46753315
A32: ⏱️ Tu dinero se duplica en: | B32: =ROUND(LN(2)/LN(1+IF(MAX(B22:F22)=B22,B15,IF(MAX(B22:F22)=C22,C15,IF(MAX(B22:F22)=D22,D15,IF(MAX(B22:F22)=E22,E15,F15))))),1)&" años" -> 5.3 años
A34: 📈 EVOLUCIÓN DE TU INVERSIÓN AÑO A AÑO
A35: Año | B35: Cuenta Ahorro | C35: CDT 90 días | D35: CDT 360 días | E35: FPV Conservador | F35: FPV Moderado
A36: 0 | B36: =$B$4*(1+B$15)^0 -> 10000000 | C36: =$B$4*(1+C$15)^0 -> 10000000 | D36: =$B$4*(1+D$15)^0 -> 10000000 | E36: =$B$4*(1+E$15)^0 -> 10000000 | F36: =$B$4*(1+F$15)^0 -> 10000000
A37: 1 | B37: =$B$4*(1+B$15)^1 -> 11157188 | C37: =$B$4*(1+C$15)^1 -> 11184229 | D37: =$B$4*(1+D$15)^1 -> 11392000 | E37: =$B$4*(1+E$15)^1 -> 10726000 | F37: =$B$4*(1+F$15)^1 -> 11042000
A38: 2 | B38: =$B$4*(1+B$15)^2 -> 12448285 | C38: =$B$4*(1+C$15)^2 -> 12508697 | D38: =$B$4*(1+D$15)^2 -> 12977766 | E38: =$B$4*(1+E$15)^2 -> 11504708 | F38: =$B$4*(1+F$15)^2 -> 12192576
A39: 3 | B39: =$B$4*(1+B$15)^3 -> 13888786 | C39: =$B$4*(1+C$15)^3 -> 13990013 | D39: =$B$4*(1+D$15)^3 -> 14784271 | E39: =$B$4*(1+E$15)^3 -> 12339949 | F39: =$B$4*(1+F$15)^3 -> 13463043
A40: 4 | B40: =$B$4*(1+B$15)^4 -> 15495980 | C40: =$B$4*(1+C$15)^4 -> 15646751 | D40: =$B$4*(1+D$15)^4 -> 16842242 | E40: =$B$4*(1+E$15)^4 -> 13235830 | F40: =$B$4*(1+F$15)^4 -> 14865892
A41: 5 | B41: =$B$4*(1+B$15)^5 -> 17289157 | C41: =$B$4*(1+C$15)^5 -> 17499684 | D41: =$B$4*(1+D$15)^5 -> 19186682 | E41: =$B$4*(1+E$15)^5 -> 14196751 | F41: =$B$4*(1+F$15)^5 -> 16414918
A42: 6 | B42: =$B$4*(1+B$15)^6 -> 19289838 | C42: =$B$4*(1+C$15)^6 -> 19572047 | D42: =$B$4*(1+D$15)^6 -> 21857468 | E42: =$B$4*(1+E$15)^6 -> 15227435 | F42: =$B$4*(1+F$15)^6 -> 18125352
A43: 7 | B43: =$B$4*(1+B$15)^7 -> 21522036 | C43: =$B$4*(1+C$15)^7 -> 21889825 | D43: =$B$4*(1+D$15)^7 -> 24900028 | E43: =$B$4*(1+E$15)^7 -> 16332947 | F43: =$B$4*(1+F$15)^7 -> 20014014
A44: 8 | B44: =$B$4*(1+B$15)^8 -> 24012541 | C44: =$B$4*(1+C$15)^8 -> 24482081 | D44: =$B$4*(1+D$15)^8 -> 28366112 | E44: =$B$4*(1+E$15)^8 -> 17518719 | F44: =$B$4*(1+F$15)^8 -> 22099474
A45: 9 | B45: =$B$4*(1+B$15)^9 -> 26791244 | C45: =$B$4*(1+C$15)^9 -> 27381319 | D45: =$B$4*(1+D$15)^9 -> 32314675 | E45: =$B$4*(1+E$15)^9 -> 18790578 | F45: =$B$4*(1+F$15)^9 -> 24402239
A46: 10 | B46: =$B$4*(1+B$15)^10 -> 29891496 | C46: =$B$4*(1+C$15)^10 -> 30623894 | D46: =$B$4*(1+D$15)^10 -> 36812877 | E46: =$B$4*(1+E$15)^10 -> 20154774 | F46: =$B$4*(1+F$15)^10 -> 26944953
...

Sheet MI META
A1: 🎯 CALCULADORA DE META DE AHORRO
A2: ¿Cuánto tiempo necesitas para alcanzar tu meta?
A3: 📝 DEFINE TU META
A4: ¿Cuánto quieres tener? | B4: 50000000 | C4: 💡 Tu meta de ahorro en pesos colombianos
A5: Tu capital inicial (del Simulador): | B5: =SIMULADOR!B4 -> 10000000 | C5: 🔗 Se toma del Simulador automáticamente
A6: Necesitas multiplicar tu dinero por: | B6: =IF(B4>B5,B4/B5,"⚠️ Meta menor al capital") -> 5
A8: ⏱️ TIEMPO PARA ALCANZAR TU META
B9: 🏦 Cuenta Ahorro | C9: 📄 CDT 90 días | D9: 📄 CDT 360 días | E9: 📈 FPV Conservador | F9: 📈 FPV Moderado
A10: 📅 Años para llegar a tu meta | B10: =IF($B$4>$B$5,LN($B$4/$B$5)/LN(1+SIMULADOR!B15),"—") -> 14.698212 | C10: =IF($B$4>$B$5,LN($B$4/$B$5)/LN(1+SIMULADOR!C15),"—") -> 14.380311 | D10: =IF($B$4>$B$5,LN($B$4/$B$5)/LN(1+SIMULADOR!D15),"—") -> 12.349299 | E10: =IF($B$4>$B$5,LN($B$4/$B$5)/LN(1+SIMULADOR!E15),"—") -> 22.963886 | F10: =IF($B$4>$B$5,LN($B$4/$B$5)/LN(1+SIMULADOR!F15),"—") -> 16.237088
A11: 📅 Equivalente en meses | B11: =IF(ISNUMBER(B10),B10*12,"—") -> 176.37854 | C11: =IF(ISNUMBER(C10),C10*12,"—") -> 172.56374 | D11: =IF(ISNUMBER(D10),D10*12,"—") -> 148.19158 | E11: =IF(ISNUMBER(E10),E10*12,"—") -> 275.56663 | F11: =IF(ISNUMBER(F10),F10*12,"—") -> 194.84506
A13: ⏱️ ¿CUÁNDO SE DUPLICA TU DINERO?
B14: 🏦 Cuenta Ahorro | C14: 📄 CDT 90 días | D14: 📄 CDT 360 días | E14: 📈 FPV Conservador | F14: 📈 FPV Moderado
A15: 📅 Años para duplicar tu capital | B15: =LN(2)/LN(1+SIMULADOR!B15) -> 6.3301752 | C15: =LN(2)/LN(1+SIMULADOR!C15) -> 6.193263 | D15: =LN(2)/LN(1+SIMULADOR!D15) -> 5.3185534 | E15: =LN(2)/LN(1+SIMULADOR!E15) -> 9.8900074 | F15: =LN(2)/LN(1+SIMULADOR!F15) -> 6.9929333
A16: Regla rápida del 72 (aprox.) | B16: =72/(SIMULADOR!B15*100) -> 6.2219775 | C16: =72/(SIMULADOR!C15*100) -> 6.0799064 | D16: =72/(SIMULADOR!D15*100) -> 5.1724138 | E16: =72/(SIMULADOR!E15*100) -> 9.9173554 | F16: =72/(SIMULADOR!F15*100) -> 6.9097889
A18: 🏆 LLEGARÁS MÁS RÁPIDO CON:
A20: 🥇 Mejor opción: | B20: =SUBSTITUTE(IF(MIN(B10:F10)=B10,B9,IF(MIN(B10:F10)=C10,C9,IF(MIN(B10:F10)=D10,D9,IF(MIN(B10:F10)=E10,E9,F9)))),CHAR(10)," ") -> 📄 CDT 360 días
A21: ⏱️ Llegarás en: | B21: =ROUND(MIN(B10:F10),1)&" años ("&ROUND(MIN(B11:F11),0)&" meses)" -> 12.3 años (148 meses)

Sheet TASAS EN VIVO
B1: 🌐 TASAS CDT EN TIEMPO REAL - COLOMBIA
B2: Datos de la Superintendencia Financiera vía datos.gov.co
B4: ⚡ TASAS VINCULADAS AL SIMULADOR
B5: Alternativa | C5: Tasa actual | D5: Estado
B6: Cuenta Ahorro | C6: =IF(F6>0,F6/100,0.08) -> 0.11 | D6: =IF(F6>0,"🔄 Dinámico (API)","✏️ Manual") -> 🔄 Dinámico (API) | F6: {=IFERROR(MAX(IF((ISNUMBER(SEARCH("DEPOSITOS DE AHORRO ACTIVOS PERSONA NATURAL",_DATOS_API!B3:B502)))*(LEFT(_DATOS_API!D3:D502,10)>="2025-06-01"),VALUE(_DATOS_API!C3:C502),0)),0)} -> 11
B7: CDT 90 días | C7: =IF(F7>0,F7/100,0.095) -> 0.1135 | D7: =IF(F7>0,"🔄 Dinámico (API)","✏️ Manual") -> 🔄 Dinámico (API) | F7: {=IFERROR(MAX(IF((ISNUMBER(SEARCH("90",_DATOS_API!B3:B502)))*(LEFT(_DATOS_API!D3:D502,10)>="2025-06-01"),VALUE(_DATOS_API!C3:C502),0)),0)} -> 11.35
B8: CDT 360 días | C8: =IF(F8>0,F8/100,0.105) -> 0.1392 | D8: =IF(F8>0,"🔄 Dinámico (API)","✏️ Manual") -> 🔄 Dinámico (API) | F8: {=IFERROR(MAX(IF((ISNUMBER(SEARCH("360",_DATOS_API!B3:B502)))*(LEFT(_DATOS_API!D3:D502,10)>="2025-06-01"),VALUE(_DATOS_API!C3:C502),0)),0)} -> 13.92
B9: FPV Conservador | C9: =IF(F9>0,F9/100,0.0587) -> 0.0726 | D9: =IF(F9>0,"🔄 Dinámico (API)","✏️ Manual") -> 🔄 Dinámico (API) | F9: {=IFERROR(MAX(IF((ISNUMBER(SEARCH("CONSERV",_DATOS_FPV!B3:B1002)))*(LEFT(_DATOS_FPV!E3:E1002,10)>="2025-06-01"),VALUE(_DATOS_FPV!D3:D1002),0)),0)} -> 7.26
B10: FPV Moderado | C10: =IF(F10>0,F10/100,0.0952) -> 0.1042 | D10: =IF(F10>0,"🔄 Dinámico (API)","✏️ Manual") -> 🔄 Dinámico (API) | F10: {=IFERROR(MAX(IF((ISNUMBER(SEARCH("MODER",_DATOS_FPV!B3:B1002)))*(LEFT(_DATOS_FPV!E3:E1002,10)>="2025-06-01"),VALUE(_DATOS_FPV!D3:D1002),0)),0)} -> 10.42
B12: 💡 Las 5 tasas son dinámicas (API). Actualiza con Datos → Actualizar todo (Ctrl+Alt+F5).
B13: ="📌 Fuente: Superintendencia Financiera de Colombia vía datos.gov.co | Banco de la República | Corte: "&CHOOSE(VALUE(MID(_DATOS_API!D3,6,2)),"enero","febrero","marzo","abril","mayo","junio","julio","agosto","septiembre","octubre","noviembre","diciembre")&" "&LEFT(_DATOS_API!D3,4) -> 📌 Fuente: Superintendencia Financiera de Colombia vía datos.gov.co | Banco de la República | Corte: marzo 2026

Sheet _DATOS_API
A1: 📥 DATOS API CDT — Tasas de Captación (datos.gov.co)
A2: nombreentidad | B2: descripcion | C2: tasa | D2: fechacorte
A3: Tuya | B3: A 90 DIAS | C3: 10.79 | D3: 2026-03-18T00:00:00.000
A4: Mibanco S.A. | B4: A 90 DIAS | C4: 11.24 | D4: 2026-03-18T00:00:00.000
A5: Findeter | B5: CAPTACIONES A TRAVES DE CDT POR TESORERIA | C5: 13.92 | D5: 2026-03-18T00:00:00.000
A6: Bancoomeva | B6: CAPTACIONES A TRAVES DE CDT POR TESORERIA | C6: 12 | D6: 2026-03-18T00:00:00.000
A7: Banco J.P. Morgan Colombia S.A., (la "Sociedad") | B7: BANCO DE LA REPUBLICA | C7: 10.25 | D7: 2026-03-18T00:00:00.000
A8: Coltefinanciera | B8: SALDO EN CUENTAS DE AHORRO ESPECIAL EN PESOS | C8: 0 | D8: 2026-03-18T00:00:00.000
A9: Bancamía S.A. | B9: SALDO EN DEPOSITOS DE AHORRO INACTIVOS Y ABANDONADOS ENTIDADES OFICIALES | C9: 0 | D9: 2026-03-18T00:00:00.000
A10: Cooperativa Financiera JFK | B10: ENTRE 121 Y 179 DIAS | C10: 8.88 | D10: 2026-03-18T00:00:00.000
A11: Coltefinanciera | B11: SALDO EN DEPOSITOS DE AHORRO INACTIVOS Y ABANDONADOS ENTIDADES OFICIALES | C11: 3.79 | D11: 2026-03-18T00:00:00.000
A12: Banco Davivienda | B12: SALDO EN CUENTAS DE AHORRO ESPECIAL EN UNIDADES DE VALOR REAL | C12: 0 | D12: 2026-03-18T00:00:00.000
A13: Banco Caja Social S.A. | B13: SALDO EN DEPOSITOS DE AHORRO ACTIVOS PERSONA JURIDICA | C13: 0 | D13: 2026-03-18T00:00:00.000
... A502: Banco de Occidente | B502: SUPERIORES A 360 DIAS | C502: 12.21 | D502: 2026-03-18T00:00:00.000

Sheet _DATOS_FPV
A1: 📥 DATOS API FPV — Fondos de Pensiones Voluntarias (datos.gov.co)
A2: nombre_entidad | B2: nombre_patrimonio | C2: nombre_subtipo_patrimonio | D2: rentabilidad_360_dias | E2: fecha_corte
A3: Skandia Afp - Accai S.A. | B3: PORTAFOLIO ESPECIAL SKANDIA C.A.T. 26 DE ABRIL DE 2027 | C3: FDOS DE PENSIONES(JUBIL-INVAL) | D3: 0.06 | E3: 2026-03-18T00:00:00.000
A4: Skandia Afp - Accai S.A. | B4: PORTAFOLIO ESPECIAL SKANDIA CAT 12 MESES - H | C4: FDOS DE PENSIONES(JUBIL-INVAL) | D4: 0.06 | E4: 2026-03-18T00:00:00.000
A5: Skandia Afp - Accai S.A. | B5: PORTAFOLIO ESPECIAL SKANDIA CAT 12 MESES - I | C5: FDOS DE PENSIONES(JUBIL-INVAL) | D5: 0.06 | E5: 2026-03-18T00:00:00.000
A6: Skandia Afp - Accai S.A. | B6: PORTAFOLIO ESPECIAL SKANDIA CAT 12 MESES - J | C6: FDOS DE PENSIONES(JUBIL-INVAL) | D6: 0.06 | E6: 2026-03-18T00:00:00.000
A7: Skandia Afp - Accai S.A. | B7: PORTAFOLIO ESPECIAL SKANDIA C.A.T. 27 DE ABRIL DE 2027 | C7: FDOS DE PENSIONES(JUBIL-INVAL) | D7: 0.06 | E7: 2026-03-18T00:00:00.000
A8: Skandia Afp - Accai S.A. | B8: PORTAFOLIO ESPECIAL SKANDIA CAT 12 MESES - K | C8: FDOS DE PENSIONES(JUBIL-INVAL) | D8: 0.07 | E8: 2026-03-18T00:00:00.000
A9: Skandia Afp - Accai S.A. | B9: PORTAFOLIO ESPECIAL SKANDIA CAT 12 MESES - L | C9: FDOS DE PENSIONES(JUBIL-INVAL) | D9: 0.07 | E9: 2026-03-18T00:00:00.000
A10: Skandia Afp - Accai S.A. | B10: PORTAFOLIO ESPECIAL SKANDIA IV 2024 | C10: FDOS DE PENSIONES(JUBIL-INVAL) | D10: 0.04 | E10: 2026-03-18T00:00:00.000
A11: Skandia Afp - Accai S.A. | B11: PORTAFOLIO ESPECIAL SKANDIA C.A.T. 28 DE ABRIL DE 2027 | C11: FDOS DE PENSIONES(JUBIL-INVAL) | D11: 0.06 | E11: 2026-03-18T00:00:00.000
A12: Skandia Afp - Accai S.A. | B12: PORTAFOLIO ESPECIAL SKANDIA C.A.T. 29 DE ABRIL DE 2027 | C12: FDOS DE PENSIONES(JUBIL-INVAL) | D12: 0.06 | E12: 2026-03-18T00:00:00.000
A13: Skandia Afp - Accai S.A. | B13: PORTAFOLIO ESPECIAL SKANDIA C.A.T. 16 DE MARZO DE 2029 | C13: FDOS DE PENSIONES(JUBIL-INVAL) | D13: 0.03 | E13: 2026-03-18T00:00:00.000
... A502: Accion Sociedad Fiduciaria S.A. Sigla Acción Fiduciaria | B502: FONDO DE PENSIONES VOLUNTARIAS MULTIACCION | C502: FDOS DE PENSIONES(JUBIL-INVAL) | D502: 6.41 | E502: 2026-03-18T00:00:00.000
